<?xml version='1.0'?>

<robot name="my_robot" xmlns:xacro="http://www.ros.org/wiki/xacro">
  
  <xacro:include filename="$(find my_robot)/urdf/my_robot.gazebo" />
  <link name="robot_footprint"></link>

  <material name="gray">
    <color rgba="0.5 0.5 0.5 1"/>
  </material> 
  
  <material name="green">
    <color rgba="0 1 0.5 1"/>
  </material>

  <joint name="robot_footprint_joint" type="fixed">
    <origin xyz="0 0 0" rpy="0 0 0" />
    <parent link="robot_footprint"/>
    <child link="chassis" />
  </joint>

  <link name='chassis'>
    <pose>0 0 0.1 0 0 0</pose>

    <inertial>
      <mass value="10.0"/>
      <origin xyz="0.0 0 0" rpy=" 0 0 0"/>
      <inertia
          ixx="0.1" ixy="0" ixz="0"
          iyy="0.1" iyz="0"
          izz="0.1"
      />
    </inertial>

    <collision name='collision'>
      <origin xyz="0 0 0" rpy=" 0 0 0"/> 
      <geometry>
        <box size=".4 .4 .05"/>
      </geometry>
    </collision>

    <visual name='chassis_visual'>
      <origin xyz="0 0 0" rpy=" 0 0 0"/>
      <geometry>
        <box size=".4 .4 .05"/>
      </geometry>
      <material name="green"/>
    </visual>

  </link>

  <link name='left_rear_wheel'>
    <inertial>
      <mass value = "5.0"/>
      <origin xyz= "0 0 0" rpy="0 1.5707 1.5707"/>
      <inertia
        ixx="0.1" ixy="0" ixz="0"
        iyy="0.1" iyz="0"
        izz="0.1"
      />
    </inertial>

    <visual>
      <origin xyz= "0 0 0" rpy="0 1.5707 1.5707"/>
      <geometry>
        <cylinder length="0.02" radius="0.1"/>
      </geometry>
      <material name="gray"/>
    </visual>
 
    <collision>
      <origin xyz= "0 0 0" rpy="0 1.5707 1.5707"/>
      <geometry>
        <cylinder length="0.02" radius="0.1"/>
      </geometry>
    </collision>

  </link>

  <link name='left_front_wheel'>
    <inertial>
      <mass value = "5.0"/>
      <origin xyz= "0 0 0" rpy="0 1.5707 1.5707"/>
      <inertia
        ixx="0.1" ixy="0" ixz="0"
        iyy="0.1" iyz="0"
        izz="0.1"
      />
    </inertial>

    <visual>
      <origin xyz= "0 0 0" rpy="0 1.5707 1.5707"/>
      <geometry>
        <cylinder length="0.02" radius="0.1"/>
      </geometry>
      <material name="gray"/>
    </visual>
 
    <collision>
      <origin xyz= "0 0 0" rpy="0 1.5707 1.5707"/>
      <geometry>
        <cylinder length="0.02" radius="0.1"/>
      </geometry>
    </collision>

  </link>


  <link name='right_rear_wheel'>
    <inertial>
      <mass value = "5.0"/>
      <origin xyz= "0 0 0" rpy="0 1.5707 1.5707"/>
      <inertia
        ixx="0.1" ixy="0" ixz="0"
        iyy="0.1" iyz="0"
        izz="0.1"
      />
    </inertial>

    <visual>
      <origin xyz= "0 0 0" rpy="0 1.5707 1.5707"/>
      <geometry>
        <cylinder length="0.02" radius="0.1"/>
      </geometry>
      <material name="gray"/>
    </visual>
 
    <collision>
      <origin xyz= "0 0 0" rpy="0 1.5707 1.5707"/>
      <geometry>
        <cylinder length="0.02" radius="0.1"/>
      </geometry>
    </collision>

  </link>

  <link name='right_front_wheel'>
    <inertial>
      <mass value = "5.0"/>
      <origin xyz= "0 0 0" rpy="0 1.5707 1.5707"/>
      <inertia
        ixx="0.1" ixy="0" ixz="0"
        iyy="0.1" iyz="0"
        izz="0.1"
      />
    </inertial>

    <visual>
      <origin xyz= "0 0 0" rpy="0 1.5707 1.5707"/>
      <geometry>
        <cylinder length="0.02" radius="0.1"/>
      </geometry>
      <material name="gray"/>
    </visual>
 
    <collision>
      <origin xyz= "0 0 0" rpy="0 1.5707 1.5707"/>
      <geometry>
        <cylinder length="0.02" radius="0.1"/>
      </geometry>
    </collision>

  </link>

  <joint type="continuous" name="left_wheel_front_hinge">
    <origin xyz="0.2 0.21 0" rpy="0 0 0"/>
    <child link="left_front_wheel"/>
    <parent link="chassis"/>
    <axis xyz="0 1 0" rpy="0 0 0"/>
    <limit effort="10000" velocity="1000"/>
    <dynamics damping="1.0" friction="1.0"/>
  </joint>

  <joint type="continuous" name="left_wheel_rear_hinge">
    <origin xyz="-0.2 0.21 0" rpy="0 0 0"/>
    <child link="left_rear_wheel"/>
    <parent link="chassis"/>
    <axis xyz="0 1 0" rpy="0 0 0"/>
    <limit effort="10000" velocity="1000"/>
    <dynamics damping="1.0" friction="1.0"/>
  </joint>



  <joint type="continuous" name="right_wheel_front_hinge">
    <origin xyz="0.2 -0.21 0" rpy="0 0 0"/>
    <child link="right_front_wheel"/>
    <parent link="chassis"/>
    <axis xyz="0 1 0" rpy="0 0 0"/>
    <limit effort="10000" velocity="1000"/>
    <dynamics damping="1.0" friction="1.0"/>
  </joint>

  <joint type="continuous" name="right_wheel_rear_hinge">
    <origin xyz="-0.2 -0.21 0" rpy="0 0 0"/>
    <child link="right_rear_wheel"/>
    <parent link="chassis"/>
    <axis xyz="0 1 0" rpy="0 0 0"/>
    <limit effort="10000" velocity="1000"/>
    <dynamics damping="1.0" friction="1.0"/>
  </joint>
  
  <link name='camera'>
    <inertial>
      <mass value="0.1"/>
      <origin xyz="0 0 0" rpy="0 0 0"/>
      <box_inertia m="0.1" x = "0.05" y ="0.05" z="0.05"/>
      <inertia
        ixx="1e-6" ixy="0" ixz="0"
        iyy="1e-6" iyz="0"
        izz="1e-6"
      />
    </inertial>
 
    <visual>
      <origin xyz="0 0 0" rpy="0 0 0"/>
      <geometry>
        <box size="0.01 0.05 0.01"/>
      </geometry>
      <material name="gray"/>
    </visual>

    <collision>
      <origin xyz="0 0 0" rpy="0 0 0"/>
      <geometry>
        <box size="0.01 0.01 0.05"/>
      </geometry>
    </collision>
  </link>

  <joint type="fixed" name="camera_joint">
    <origin xyz="0.2 0 0" rpy="0 0 0"/>
    <child link="camera"/>
    <parent link="chassis"/>
    <axis xyz="0 1 0" rpy="0 0 0"/>
  </joint>
  
  <link name="hokuyo">
    <inertial>
      <mass value="1e-5"/>
      <origin xyz="0 0 0" rpy="0 0 0"/>
      <inertia
        ixx="1e-6" ixy="0" ixz="0"
        iyy="1e-6" iyz="0"
        izz="1e-6"
      />
    </inertial>

    <visual>
      <origin xyz="0 0 0" rpy="0 0 0"/>
      <geometry>
        <mesh filename="package://my_robot/meshes/hokuyo.dae"/>
      </geometry>
    </visual>

    <collision>
      <origin xyz="0 0 0" rpy="0 0 0"/>
      <geometry>
        <box size="0.1 0.1 0.1"/>
      </geometry>
    </collision>
  </link>

  <joint type="fixed" name="hokuyo_joint">
    <origin xyz="0.15 0 0.05" rpy="0 0 0"/>
    <child link="hokuyo"/>
    <parent link="chassis"/>
    <axis xyz="0 1 0" rpy="0 0 0"/>
  </joint>

  <joint name="camera_optical_joint" type="fixed">
    <origin xyz="0 0 0" rpy="-1.5707 0 -1.5707"/>
    <parent link="camera"/>
    <child link="camera_link_optical"/>
  </joint>

  <link name="camera_link_optical">
    <inertial>
      <mass value="0.1"/>
      <origin xyz="0 0 0" rpy="0 0 0"/>
      <box_inertia m="0.1" x = "0.05" y ="0.05" z="0.05"/>
      <inertia
        ixx="1e-6" ixy="0" ixz="0"
        iyy="1e-6" iyz="0"
        izz="1e-6"
      />
    </inertial>
 
    <visual>
      <origin xyz="0 0 0" rpy="0 0 0"/>
      <geometry>
        <box size="0.01 0.05 0.01"/>
      </geometry>
      <material name="gray"/>
    </visual>

    <collision>
      <origin xyz="0 0 0" rpy="0 0 0"/>
      <geometry>
        <box size="0.01 0.01 0.05"/>
      </geometry>
    </collision>
  </link>


</robot>
